Workbook

Sheet Instructions
B2: AnI-HealthcareServices — Doctors & Availability Configuration
B3: This workbook is the master list of doctors, their weekly OPD availability, department OPD days, leave and slot settings.
B5: Colour legend
B6: Cream cells | C6: You edit these. Most have a dropdown — pick from the list.
B7: Grey cells | C7: Calculated automatically (formulas). Don't type over them.
B8: Green cells | C8: Reference only (IDs, names and codes that the website relies on). Don't change.
B10: Sheets
B11: Doctors | C11: One row per doctor: profile + weekly availability Mon–Sat (Full day / AM only / PM only / Off). Row order = order on the website.
B12: Departments | C12: OPD days per department (Open/Closed) and whether the consultation fee is General or Specialist. Shows head and doctor count.
B13: Leave | C13: Dates a doctor is away. Approved leave blocks that doctor's booking slots on those dates.
B14: Settings | C14: Session timings, slot length, booking window and consultation fees.
B15: Weekly Coverage | C15: Read-only: how many active doctors each department has in each morning/afternoon session. Red 0 = OPD open but nobody available.
B17: How to apply changes
B18: Step 1 | C18: Edit the cream cells in this workbook and save it (keep the file name and .xlsx format).
B19: Step 2 | C19: Check it: python tools/doctors_config.py check — lists any mistakes with the sheet and row.
B20: Step 3 | C20: Apply it: python tools/doctors_config.py sync — updates the website (doctor list, OPD days) and the staff portal (staff directory, availability, leave, slot settings).
B21: Step 4 | C21: Commit and push to GitHub. Vercel and GitHub Pages redeploy automatically within a minute or two.
B22: Step 5 | C22: Each browser picks up the new configuration on its next visit. The workbook wins: changes made to these same fields inside the portal (e.g. a doctor's weekly pattern) are replaced on the next sync.
B24: Rules
B25: • | C25: Staff ID: STF + 4 digits, unique. For a new doctor use the next free ID shown below. Never reuse an old ID.
B26: • | C26: To remove a doctor, set Status = Inactive (keeps their appointment history). Inactive doctors disappear from the website and booking.
B27: • | C27: On Leave doctors stay on the website but can't be booked. For specific dates, add a row on the Leave sheet instead.
B28: • | C28: Show on website = No hides a doctor from the public 'Find a doctor' list but keeps them bookable in the portal.
B29: • | C29: Each department should have exactly one 'Professor & Head' — that name is shown as the head of department.
B30: • | C30: Emergency Care is walk-in 24×7; its OPD days don't limit emergencies.
B31: • | C31: Mobile: 10 digits starting 6–9. Email may be left blank — it is generated as firstname.lastname@ani-healthcareservices.example.
B33: Next free Staff ID | C33: ="STF"&TEXT(MAX(Doctors!$V$2:$V$200,20)+1,"0000")
C34: IDs STF0011–STF0020 belong to nurses, technicians and other non-doctor staff.
B36: Example — adding leave
B37: Staff ID | C37: STF0006
B38: Doctor (auto) | C38: Dr. Vikram Singh
B39: Leave type | C39: Conference leave
B40: From | C40: 46342
B41: To | C41: 46344
B42: Days (auto) | C42: 3
B43: Reason | C43: Neurology conference, Delhi
B44: Status | C44: Approved
C45: This is only an example — it is not part of the configuration. Add real leave on the Leave sheet.

Sheet Doctors
A1: Staff ID | B1: Doctor name | C1: Department | D1: Qualification | E1: Designation | F1: Employment | G1: Experience (yrs) | H1: Date of joining | I1: Mobile | J1: Email | K1: Status | L1: Show on website | M1: Mon | N1: Tue | O1: Wed | P1: Thu | Q1: Fri | R1: Sat | S1: OPD sessions / week | T1: Check | U1: key | V1: id# | W1: dept#
A2: STF0001 | B2: Dr. Meera Iyer | C2: Cardiology | D2: MD, DM (Cardiology) | E2: Professor & Head | F2: Permanent | G2: 22 | H2: 38169 | I2: 9845010000 | J2: meera.iyer@ani-healthcareservices.example | K2: Active | L2: Yes | M2: Full | N2: Off | O2: Full | P2: Off | Q2: Full | R2: AM | S2: =IF(A2="","",COUNTIF(M2:R2,"Full")*2+COUNTIF(M2:R2,"AM")+COUNTIF(M2:R2,"PM")) | T2: =IF(A2="","",IF(COUNTIF($A$2:$A$200,A2)>1,"Duplicate Staff ID",IF(COUNTA(B2:I2)+COUNTA(K2:L2)<10,"Fill in all details",IF($W2="","Pick a department",IF(COUNTIF(M2:R2,"Off")=6,"No OPD days set",IF((M2<>"Off")*(INDEX(Departments!$D$2:$D$13,$W2)="Closed")+(N2<>"Off")*(INDEX(Departments!$E$2:$E$13,$W2)="Closed")+(O2<>"Off")*(INDEX(Departments!$F$2:$F$13,$W2)="Closed")+(P2<>"Off")*(INDEX(Departments!$G$2:$G$13,$W2)="Closed")+(Q2<>"Off")*(INDEX(Departments!$H$2:$H$13,$W2)="Closed")+(R2<>"Off")*(INDEX(Departments!$I$2:$I$13,$W2)="Closed")>0,"Note: works on a closed OPD day","OK")))))) | U2: =C2&"|"&E2 | V2: =IF(A2="","",IFERROR(VALUE(MID(A2,4,4)),0)) | W2: =IFERROR(MATCH(C2,Departments!$B$2:$B$13,0),"")
A3: STF0002 | B3: Dr. Arjun Rao | C3: Orthopaedics | D3: MS (Ortho), Fellowship Arthroplasty | E3: Professor & Head | F3: Permanent | G3: 18 | H3: 39614 | I3: 9845010137 | J3: arjun.rao@ani-healthcareservices.example | K3: Active | L3: Yes | M3: Full | N3: Full | O3: Off | P3: Full | Q3: Full | R3: Full | S3: =IF(A3="","",COUNTIF(M3:R3,"Full")*2+COUNTIF(M3:R3,"AM")+COUNTIF(M3:R3,"PM")) | T3: =IF(A3="","",IF(COUNTIF($A$2:$A$200,A3)>1,"Duplicate Staff ID",IF(COUNTA(B3:I3)+COUNTA(K3:L3)<10,"Fill in all details",IF($W3="","Pick a department",IF(COUNTIF(M3:R3,"Off")=6,"No OPD days set",IF((M3<>"Off")*(INDEX(Departments!$D$2:$D$13,$W3)="Closed")+(N3<>"Off")*(INDEX(Departments!$E$2:$E$13,$W3)="Closed")+(O3<>"Off")*(INDEX(Departments!$F$2:$F$13,$W3)="Closed")+(P3<>"Off")*(INDEX(Departments!$G$2:$G$13,$W3)="Closed")+(Q3<>"Off")*(INDEX(Departments!$H$2:$H$13,$W3)="Closed")+(R3<>"Off")*(INDEX(Departments!$I$2:$I$13,$W3)="Closed")>0,"Note: works on a closed OPD day","OK")))))) | U3: =C3&"|"&E3 | V3: =IF(A3="","",IFERROR(VALUE(MID(A3,4,4)),0)) | W3: =IFERROR(MATCH(C3,Departments!$B$2:$B$13,0),"")
A4: STF0003 | B4: Dr. Fatima Sheikh | C4: Paediatrics | D4: MD (Paediatrics) | E4: Professor & Head | F4: Permanent | G4: 12 | H4: 41649 | I4: 9845010274 | J4: fatima.sheikh@ani-healthcareservices.example | K4: Active | L4: Yes | M4: Full | N4: Full | O4: Full | P4: Full | Q4: Full | R4: Full | S4: =IF(A4="","",COUNTIF(M4:R4,"Full")*2+COUNTIF(M4:R4,"AM")+COUNTIF(M4:R4,"PM")) | T4: =IF(A4="","",IF(COUNTIF($A$2:$A$200,A4)>1,"Duplicate Staff ID",IF(COUNTA(B4:I4)+COUNTA(K4:L4)<10,"Fill in all details",IF($W4="","Pick a department",IF(COUNTIF(M4:R4,"Off")=6,"No OPD days set",IF((M4<>"Off")*(INDEX(Departments!$D$2:$D$13,$W4)="Closed")+(N4<>"Off")*(INDEX(Departments!$E$2:$E$13,$W4)="Closed")+(O4<>"Off")*(INDEX(Departments!$F$2:$F$13,$W4)="Closed")+(P4<>"Off")*(INDEX(Departments!$G$2:$G$13,$W4)="Closed")+(Q4<>"Off")*(INDEX(Departments!$H$2:$H$13,$W4)="Closed")+(R4<>"Off")*(INDEX(Departments!$I$2:$I$13,$W4)="Closed")>0,"Note: works on a closed OPD day","OK")))))) | U4: =C4&"|"&E4 | V4: =IF(A4="","",IFERROR(VALUE(MID(A4,4,4)),0)) | W4: =IFERROR(MATCH(C4,Departments!$B$2:$B$13,0),"")
A5: STF0004 | B5: Dr. Rohan Kulkarni | C5: General Medicine | D5: MD (General Medicine) | E5: Professor & Head | F5: Permanent | G5: 25 | H5: 36951 | I5: 9845010411 | J5: rohan.kulkarni@ani-healthcareservices.example | K5: Active | L5: Yes | M5: Full | N5: Full | O5: Full | P5: Full | Q5: Full | R5: AM | S5: =IF(A5="","",COUNTIF(M5:R5,"Full")*2+COUNTIF(M5:R5,"AM")+COUNTIF(M5:R5,"PM")) | T5: =IF(A5="","",IF(COUNTIF($A$2:$A$200,A5)>1,"Duplicate Staff ID",IF(COUNTA(B5:I5)+COUNTA(K5:L5)<10,"Fill in all details",IF($W5="","Pick a department",IF(COUNTIF(M5:R5,"Off")=6,"No OPD days set",IF((M5<>"Off")*(INDEX(Departments!$D$2:$D$13,$W5)="Closed")+(N5<>"Off")*(INDEX(Departments!$E$2:$E$13,$W5)="Closed")+(O5<>"Off")*(INDEX(Departments!$F$2:$F$13,$W5)="Closed")+(P5<>"Off")*(INDEX(Departments!$G$2:$G$13,$W5)="Closed")+(Q5<>"Off")*(INDEX(Departments!$H$2:$H$13,$W5)="Closed")+(R5<>"Off")*(INDEX(Departments!$I$2:$I$13,$W5)="Closed")>0,"Note: works on a closed OPD day","OK")))))) | U5: =C5&"|"&E5 | V5: =IF(A5="","",IFERROR(VALUE(MID(A5,4,4)),0)) | W5: =IFERROR(MATCH(C5,Departments!$B$2:$B$13,0),"")
A6: STF0005 | B6: Dr. Anjali Nair | C6: Obstetrics & Gynaecology | D6: MS, DNB (OBG) | E6: Professor & Head | F6: Permanent | G6: 14 | H6: 41141 | I6: 9845010548 | J6: anjali.nair@ani-healthcareservices.example | K6: Active | L6: Yes | M6: Full | N6: Full | O6: Full | P6: Full | Q6: Full | R6: Full | S6: =IF(A6="","",COUNTIF(M6:R6,"Full")*2+COUNTIF(M6:R6,"AM")+COUNTIF(M6:R6,"PM")) | T6: =IF(A6="","",IF(COUNTIF($A$2:$A$200,A6)>1,"Duplicate Staff ID",IF(COUNTA(B6:I6)+COUNTA(K6:L6)<10,"Fill in all details",IF($W6="","Pick a department",IF(COUNTIF(M6:R6,"Off")=6,"No OPD days set",IF((M6<>"Off")*(INDEX(Departments!$D$2:$D$13,$W6)="Closed")+(N6<>"Off")*(INDEX(Departments!$E$2:$E$13,$W6)="Closed")+(O6<>"Off")*(INDEX(Departments!$F$2:$F$13,$W6)="Closed")+(P6<>"Off")*(INDEX(Departments!$G$2:$G$13,$W6)="Closed")+(Q6<>"Off")*(INDEX(Departments!$H$2:$H$13,$W6)="Closed")+(R6<>"Off")*(INDEX(Departments!$I$2:$I$13,$W6)="Closed")>0,"Note: works on a closed OPD day","OK")))))) | U6: =C6&"|"&E6 | V6: =IF(A6="","",IFERROR(VALUE(MID(A6,4,4)),0)) | W6: =IFERROR(MATCH(C6,Departments!$B$2:$B$13,0),"")
A7: STF0006 | B7: Dr. Vikram Singh | C7: Neurology | D7: MCh (Neurosurgery) | E7: Professor & Head | F7: Permanent | G7: 9 | H7: 43040 | I7: 9845010685 | J7: vikram.singh@ani-healthcareservices.example | K7: Active | L7: Yes | M7: Off | N7: Full | O7: Off | P7: Full | Q7: Off | R7: Full | S7: =IF(A7="","",COUNTIF(M7:R7,"Full")*2+COUNTIF(M7:R7,"AM")+COUNTIF(M7:R7,"PM")) | T7: =IF(A7="","",IF(COUNTIF($A$2:$A$200,A7)>1,"Duplicate Staff ID",IF(COUNTA(B7:I7)+COUNTA(K7:L7)<10,"Fill in all details",IF($W7="","Pick a department",IF(COUNTIF(M7:R7,"Off")=6,"No OPD days set",IF((M7<>"Off")*(INDEX(Departments!$D$2:$D$13,$W7)="Closed")+(N7<>"Off")*(INDEX(Departments!$E$2:$E$13,$W7)="Closed")+(O7<>"Off")*(INDEX(Departments!$F$2:$F$13,$W7)="Closed")+(P7<>"Off")*(INDEX(Departments!$G$2:$G$13,$W7)="Closed")+(Q7<>"Off")*(INDEX(Departments!$H$2:$H$13,$W7)="Closed")+(R7<>"Off")*(INDEX(Departments!$I$2:$I$13,$W7)="Closed")>0,"Note: works on a closed OPD day","OK")))))) | U7: =C7&"|"&E7 | V7: =IF(A7="","",IFERROR(VALUE(MID(A7,4,4)),0)) | W7: =IFERROR(MATCH(C7,Departments!$B$2:$B$13,0),"")
A8: STF0007 | B8: Dr. Kavya Menon | C8: Ophthalmology | D8: MS (Ophthalmology) | E8: Professor & Head | F8: Permanent | G8: 11 | H8: 42128 | I8: 9845010822 | J8: kavya.menon@ani-healthcareservices.example | K8: Active | L8: Yes | M8: Full | N8: Full | O8: Full | P8: Full | Q8: Full | R8: AM | S8: =IF(A8="","",COUNTIF(M8:R8,"Full")*2+COUNTIF(M8:R8,"AM")+COUNTIF(M8:R8,"PM")) | T8: =IF(A8="","",IF(COUNTIF($A$2:$A$200,A8)>1,"Duplicate Staff ID",IF(COUNTA(B8:I8)+COUNTA(K8:L8)<10,"Fill in all details",IF($W8="","Pick a department",IF(COUNTIF(M8:R8,"Off")=6,"No OPD days set",IF((M8<>"Off")*(INDEX(Departments!$D$2:$D$13,$W8)="Closed")+(N8<>"Off")*(INDEX(Departments!$E$2:$E$13,$W8)="Closed")+(O8<>"Off")*(INDEX(Departments!$F$2:$F$13,$W8)="Closed")+(P8<>"Off")*(INDEX(Departments!$G$2:$G$13,$W8)="Closed")+(Q8<>"Off")*(INDEX(Departments!$H$2:$H$13,$W8)="Closed")+(R8<>"Off")*(INDEX(Departments!$I$2:$I$13,$W8)="Closed")>0,"Note: works on a closed OPD day","OK")))))) | U8: =C8&"|"&E8 | V8: =IF(A8="","",IFERROR(VALUE(MID(A8,4,4)),0)) | W8: =IFERROR(MATCH(C8,Departments!$B$2:$B$13,0),"")
A9: STF0008 | B9: Dr. Sameer Joshi | C9: General Surgery | D9: MS (General Surgery), FMAS | E9: Professor & Head | F9: Permanent | G9: 20 | H9: 38762 | I9: 9845010959 | J9: sameer.joshi@ani-healthcareservices.example | K9: Active | L9: Yes | M9: Full | N9: Full | O9: Full | P9: Full | Q9: Full | R9: Full | S9: =IF(A9="","",COUNTIF(M9:R9,"Full")*2+COUNTIF(M9:R9,"AM")+COUNTIF(M9:R9,"PM")) | T9: =IF(A9="","",IF(COUNTIF($A$2:$A$200,A9)>1,"Duplicate Staff ID",IF(COUNTA(B9:I9)+COUNTA(K9:L9)<10,"Fill in all details",IF($W9="","Pick a department",IF(COUNTIF(M9:R9,"Off")=6,"No OPD days set",IF((M9<>"Off")*(INDEX(Departments!$D$2:$D$13,$W9)="Closed")+(N9<>"Off")*(INDEX(Departments!$E$2:$E$13,$W9)="Closed")+(O9<>"Off")*(INDEX(Departments!$F$2:$F$13,$W9)="Closed")+(P9<>"Off")*(INDEX(Departments!$G$2:$G$13,$W9)="Closed")+(Q9<>"Off")*(INDEX(Departments!$H$2:$H$13,$W9)="Closed")+(R9<>"Off")*(INDEX(Departments!$I$2:$I$13,$W9)="Closed")>0,"Note: works on a closed OPD day","OK")))))) | U9: =C9&"|"&E9 | V9: =IF(A9="","",IFERROR(VALUE(MID(A9,4,4)),0)) | W9: =IFERROR(MATCH(C9,Departments!$B$2:$B$13,0),"")
A10: STF0009 | B10: Dr. Priya Das | C10: ENT | D10: MS (ENT) | E10: Professor & Head | F10: Contract | G10: 7 | H10: 43717 | I10: 9845011096 | J10: priya.das@ani-healthcareservices.example | K10: Active | L10: Yes | M10: Full | N10: Off | O10: Full | P10: Off | Q10: Full | R10: Off | S10: =IF(A10="","",COUNTIF(M10:R10,"Full")*2+COUNTIF(M10:R10,"AM")+COUNTIF(M10:R10,"PM")) | T10: =IF(A10="","",IF(COUNTIF($A$2:$A$200,A10)>1,"Duplicate Staff ID",IF(COUNTA(B10:I10)+COUNTA(K10:L10)<10,"Fill in all details",IF($W10="","Pick a department",IF(COUNTIF(M10:R10,"Off")=6,"No OPD days set",IF((M10<>"Off")*(INDEX(Departments!$D$2:$D$13,$W10)="Closed")+(N10<>"Off")*(INDEX(Departments!$E$2:$E$13,$W10)="Closed")+(O10<>"Off")*(INDEX(Departments!$F$2:$F$13,$W10)="Closed")+(P10<>"Off")*(INDEX(Departments!$G$2:$G$13,$W10)="Closed")+(Q10<>"Off")*(INDEX(Departments!$H$2:$H$13,$W10)="Closed")+(R10<>"Off")*(INDEX(Departments!$I$2:$I$13,$W10)="Closed")>0,"Note: works on a closed OPD day","OK")))))) | U10: =C10&"|"&E10 | V10: =IF(A10="","",IFERROR(VALUE(MID(A10,4,4)),0)) | W10: =IFERROR(MATCH(C10,Departments!$B$2:$B$13,0),"")
A11: STF0021 | B11: Dr. Sanjay Hegde | C11: General Medicine | D11: MD (General Medicine) | E11: Associate Professor | F11: Permanent | G11: 15 | H11: 40725 | I11: 9845012740 | J11: sanjay.hegde@ani-healthcareservices.example | K11: Active | L11: Yes | M11: Full | N11: Full | O11: Full | P11: Full | Q11: Full | R11: Full | S11: =IF(A11="","",COUNTIF(M11:R11,"Full")*2+COUNTIF(M11:R11,"AM")+COUNTIF(M11:R11,"PM")) | T11: =IF(A11="","",IF(COUNTIF($A$2:$A$200,A11)>1,"Duplicate Staff ID",IF(COUNTA(B11:I11)+COUNTA(K11:L11)<10,"Fill in all details",IF($W11="","Pick a department",IF(COUNTIF(M11:R11,"Off")=6,"No OPD days set",IF((M11<>"Off")*(INDEX(Departments!$D$2:$D$13,$W11)="Closed")+(N11<>"Off")*(INDEX(Departments!$E$2:$E$13,$W11)="Closed")+(O11<>"Off")*(INDEX(Departments!$F$2:$F$13,$W11)="Closed")+(P11<>"Off")*(INDEX(Departments!$G$2:$G$13,$W11)="Closed")+(Q11<>"Off")*(INDEX(Departments!$H$2:$H$13,$W11)="Closed")+(R11<>"Off")*(INDEX(Departments!$I$2:$I$13,$W11)="Closed")>0,"Note: works on a closed OPD day","OK")))))) | U11: =C11&"|"&E11 | V11: =IF(A11="","",IFERROR(VALUE(MID(A11,4,4)),0)) | W11: =IFERROR(MATCH(C11,Departments!$B$2:$B$13,0),"")
A12: STF0022 | B12: Dr. Nandini Shetty | C12: General Medicine | D12: MD (General Medicine) | E12: Assistant Professor | F12: Permanent | G12: 8 | H12: 43328 | I12: 9845012877 | J12: nandini.shetty@ani-healthcareservices.example | K12: Active | L12: Yes | M12: Full | N12: Full | O12: Full | P12: Full | Q12: Full | R12: Full | S12: =IF(A12="","",COUNTIF(M12:R12,"Full")*2+COUNTIF(M12:R12,"AM")+COUNTIF(M12:R12,"PM")) | T12: =IF(A12="","",IF(COUNTIF($A$2:$A$200,A12)>1,"Duplicate Staff ID",IF(COUNTA(B12:I12)+COUNTA(K12:L12)<10,"Fill in all details",IF($W12="","Pick a department",IF(COUNTIF(M12:R12,"Off")=6,"No OPD days set",IF((M12<>"Off")*(INDEX(Departments!$D$2:$D$13,$W12)="Closed")+(N12<>"Off")*(INDEX(Departments!$E$2:$E$13,$W12)="Closed")+(O12<>"Off")*(INDEX(Departments!$F$2:$F$13,$W12)="Closed")+(P12<>"Off")*(INDEX(Departments!$G$2:$G$13,$W12)="Closed")+(Q12<>"Off")*(INDEX(Departments!$H$2:$H$13,$W12)="Closed")+(R12<>"Off")*(INDEX(Departments!$I$2:$I$13,$W12)="Closed")>0,"Note: works on a closed OPD day","OK")))))) | U12: =C12&"|"&E12 | V12: =IF(A12="","",IFERROR(VALUE(MID(A12,4,4)),0)) | W12: =IFERROR(MATCH(C12,Departments!$B$2:$B$13,0),"")
A13: STF0023 | B13: Dr. Karthik Shenoy | C13: General Surgery | D13: MS (General Surgery) | E13: Associate Professor | F13: Permanent | G13: 13 | H13: 41309 | I13: 9845013014 | J13: karthik.shenoy@ani-healthcareservices.example | K13: Active | L13: Yes | M13: Full | N13: Full | O13: Full | P13: Full | Q13: Full | R13: AM | S13: =IF(A13="","",COUNTIF(M13:R13,"Full")*2+COUNTIF(M13:R13,"AM")+COUNTIF(M13:R13,"PM")) | T13: =IF(A13="","",IF(COUNTIF($A$2:$A$200,A13)>1,"Duplicate Staff ID",IF(COUNTA(B13:I13)+COUNTA(K13:L13)<10,"Fill in all details",IF($W13="","Pick a department",IF(COUNTIF(M13:R13,"Off")=6,"No OPD days set",IF((M13<>"Off")*(INDEX(Departments!$D$2:$D$13,$W13)="Closed")+(N13<>"Off")*(INDEX(Departments!$E$2:$E$13,$W13)="Closed")+(O13<>"Off")*(INDEX(Departments!$F$2:$F$13,$W13)="Closed")+(P13<>"Off")*(INDEX(Departments!$G$2:$G$13,$W13)="Closed")+(Q13<>"Off")*(INDEX(Departments!$H$2:$H$13,$W13)="Closed")+(R13<>"Off")*(INDEX(Departments!$I$2:$I$13,$W13)="Closed")>0,"Note: works on a closed OPD day","OK")))))) | U13: =C13&"|"&E13 | V13: =IF(A13="","",IFERROR(VALUE(MID(A13,4,4)),0)) | W13: =IFERROR(MATCH(C13,Departments!$B$2:$B$13,0),"")
... A37: STF0044 | B37: Dr. Nisha Agarwal | C37: Radiology | D37: DNB (Radiology) | E37: Assistant Professor | F37: Permanent | G37: 5 | H37: 44291 | I37: 9845015891 | J37: nisha.agarwal@ani-healthcareservices.example | K37: Active | L37: Yes | M37: Full | N37: Full | O37: Full | P37: Full | Q37: Full | R37: AM | S37: =IF(A37="","",COUNTIF(M37:R37,"Full")*2+COUNTIF(M37:R37,"AM")+COUNTIF(M37:R37,"PM")) | T37: =IF(A37="","",IF(COUNTIF($A$2:$A$200,A37)>1,"Duplicate Staff ID",IF(COUNTA(B37:I37)+COUNTA(K37:L37)<10,"Fill in all details",IF($W37="","Pick a department",IF(COUNTIF(M37:R37,"Off")=6,"No OPD days set",IF((M37<>"Off")*(INDEX(Departments!$D$2:$D$13,$W37)="Closed")+(N37<>"Off")*(INDEX(Departments!$E$2:$E$13,$W37)="Closed")+(O37<>"Off")*(INDEX(Departments!$F$2:$F$13,$W37)="Closed")+(P37<>"Off")*(INDEX(Departments!$G$2:$G$13,$W37)="Closed")+(Q37<>"Off")*(INDEX(Departments!$H$2:$H$13,$W37)="Closed")+(R37<>"Off")*(INDEX(Departments!$I$2:$I$13,$W37)="Closed")>0,"Note: works on a closed OPD day","OK")))))) | U37: =C37&"|"&E37 | V37: =IF(A37="","",IFERROR(VALUE(MID(A37,4,4)),0)) | W37: =IFERROR(MATCH(C37,Departments!$B$2:$B$13,0),"")
S38: =IF(A38="","",COUNTIF(M38:R38,"Full")*2+COUNTIF(M38:R38,"AM")+COUNTIF(M38:R38,"PM")) | T38: =IF(A38="","",IF(COUNTIF($A$2:$A$200,A38)>1,"Duplicate Staff ID",IF(COUNTA(B38:I38)+COUNTA(K38:L38)<10,"Fill in all details",IF($W38="","Pick a department",IF(COUNTIF(M38:R38,"Off")=6,"No OPD days set",IF((M38<>"Off")*(INDEX(Departments!$D$2:$D$13,$W38)="Closed")+(N38<>"Off")*(INDEX(Departments!$E$2:$E$13,$W38)="Closed")+(O38<>"Off")*(INDEX(Departments!$F$2:$F$13,$W38)="Closed")+(P38<>"Off")*(INDEX(Departments!$G$2:$G$13,$W38)="Closed")+(Q38<>"Off")*(INDEX(Departments!$H$2:$H$13,$W38)="Closed")+(R38<>"Off")*(INDEX(Departments!$I$2:$I$13,$W38)="Closed")>0,"Note: works on a closed OPD day","OK")))))) | U38: =C38&"|"&E38 | V38: =IF(A38="","",IFERROR(VALUE(MID(A38,4,4)),0)) | W38: =IFERROR(MATCH(C38,Departments!$B$2:$B$13,0),"")
S39: =IF(A39="","",COUNTIF(M39:R39,"Full")*2+COUNTIF(M39:R39,"AM")+COUNTIF(M39:R39,"PM")) | T39: =IF(A39="","",IF(COUNTIF($A$2:$A$200,A39)>1,"Duplicate Staff ID",IF(COUNTA(B39:I39)+COUNTA(K39:L39)<10,"Fill in all details",IF($W39="","Pick a department",IF(COUNTIF(M39:R39,"Off")=6,"No OPD days set",IF((M39<>"Off")*(INDEX(Departments!$D$2:$D$13,$W39)="Closed")+(N39<>"Off")*(INDEX(Departments!$E$2:$E$13,$W39)="Closed")+(O39<>"Off")*(INDEX(Departments!$F$2:$F$13,$W39)="Closed")+(P39<>"Off")*(INDEX(Departments!$G$2:$G$13,$W39)="Closed")+(Q39<>"Off")*(INDEX(Departments!$H$2:$H$13,$W39)="Closed")+(R39<>"Off")*(INDEX(Departments!$I$2:$I$13,$W39)="Closed")>0,"Note: works on a closed OPD day","OK")))))) | U39: =C39&"|"&E39 | V39: =IF(A39="","",IFERROR(VALUE(MID(A39,4,4)),0)) | W39: =IFERROR(MATCH(C39,Departments!$B$2:$B$13,0),"")
S40: =IF(A40="","",COUNTIF(M40:R40,"Full")*2+COUNTIF(M40:R40,"AM")+COUNTIF(M40:R40,"PM")) | T40: =IF(A40="","",IF(COUNTIF($A$2:$A$200,A40)>1,"Duplicate Staff ID",IF(COUNTA(B40:I40)+COUNTA(K40:L40)<10,"Fill in all details",IF($W40="","Pick a department",IF(COUNTIF(M40:R40,"Off")=6,"No OPD days set",IF((M40<>"Off")*(INDEX(Departments!$D$2:$D$13,$W40)="Closed")+(N40<>"Off")*(INDEX(Departments!$E$2:$E$13,$W40)="Closed")+(O40<>"Off")*(INDEX(Departments!$F$2:$F$13,$W40)="Closed")+(P40<>"Off")*(INDEX(Departments!$G$2:$G$13,$W40)="Closed")+(Q40<>"Off")*(INDEX(Departments!$H$2:$H$13,$W40)="Closed")+(R40<>"Off")*(INDEX(Departments!$I$2:$I$13,$W40)="Closed")>0,"Note: works on a closed OPD day","OK")))))) | U40: =C40&"|"&E40 | V40: =IF(A40="","",IFERROR(VALUE(MID(A40,4,4)),0)) | W40: =IFERROR(MATCH(C40,Departments!$B$2:$B$13,0),"")
S41: =IF(A41="","",COUNTIF(M41:R41,"Full")*2+COUNTIF(M41:R41,"AM")+COUNTIF(M41:R41,"PM")) | T41: =IF(A41="","",IF(COUNTIF($A$2:$A$200,A41)>1,"Duplicate Staff ID",IF(COUNTA(B41:I41)+COUNTA(K41:L41)<10,"Fill in all details",IF($W41="","Pick a department",IF(COUNTIF(M41:R41,"Off")=6,"No OPD days set",IF((M41<>"Off")*(INDEX(Departments!$D$2:$D$13,$W41)="Closed")+(N41<>"Off")*(INDEX(Departments!$E$2:$E$13,$W41)="Closed")+(O41<>"Off")*(INDEX(Departments!$F$2:$F$13,$W41)="Closed")+(P41<>"Off")*(INDEX(Departments!$G$2:$G$13,$W41)="Closed")+(Q41<>"Off")*(INDEX(Departments!$H$2:$H$13,$W41)="Closed")+(R41<>"Off")*(INDEX(Departments!$I$2:$I$13,$W41)="Closed")>0,"Note: works on a closed OPD day","OK")))))) | U41: =C41&"|"&E41 | V41: =IF(A41="","",IFERROR(VALUE(MID(A41,4,4)),0)) | W41: =IFERROR(MATCH(C41,Departments!$B$2:$B$13,0),"")
S42: =IF(A42="","",COUNTIF(M42:R42,"Full")*2+COUNTIF(M42:R42,"AM")+COUNTIF(M42:R42,"PM")) | T42: =IF(A42="","",IF(COUNTIF($A$2:$A$200,A42)>1,"Duplicate Staff ID",IF(COUNTA(B42:I42)+COUNTA(K42:L42)<10,"Fill in all details",IF($W42="","Pick a department",IF(COUNTIF(M42:R42,"Off")=6,"No OPD days set",IF((M42<>"Off")*(INDEX(Departments!$D$2:$D$13,$W42)="Closed")+(N42<>"Off")*(INDEX(Departments!$E$2:$E$13,$W42)="Closed")+(O42<>"Off")*(INDEX(Departments!$F$2:$F$13,$W42)="Closed")+(P42<>"Off")*(INDEX(Departments!$G$2:$G$13,$W42)="Closed")+(Q42<>"Off")*(INDEX(Departments!$H$2:$H$13,$W42)="Closed")+(R42<>"Off")*(INDEX(Departments!$I$2:$I$13,$W42)="Closed")>0,"Note: works on a closed OPD day","OK")))))) | U42: =C42&"|"&E42 | V42: =IF(A42="","",IFERROR(VALUE(MID(A42,4,4)),0)) | W42: =IFERROR(MATCH(C42,Departments!$B$2:$B$13,0),"")
S43: =IF(A43="","",COUNTIF(M43:R43,"Full")*2+COUNTIF(M43:R43,"AM")+COUNTIF(M43:R43,"PM")) | T43: =IF(A43="","",IF(COUNTIF($A$2:$A$200,A43)>1,"Duplicate Staff ID",IF(COUNTA(B43:I43)+COUNTA(K43:L43)<10,"Fill in all details",IF($W43="","Pick a department",IF(COUNTIF(M43:R43,"Off")=6,"No OPD days set",IF((M43<>"Off")*(INDEX(Departments!$D$2:$D$13,$W43)="Closed")+(N43<>"Off")*(INDEX(Departments!$E$2:$E$13,$W43)="Closed")+(O43<>"Off")*(INDEX(Departments!$F$2:$F$13,$W43)="Closed")+(P43<>"Off")*(INDEX(Departments!$G$2:$G$13,$W43)="Closed")+(Q43<>"Off")*(INDEX(Departments!$H$2:$H$13,$W43)="Closed")+(R43<>"Off")*(INDEX(Departments!$I$2:$I$13,$W43)="Closed")>0,"Note: works on a closed OPD day","OK")))))) | U43: =C43&"|"&E43 | V43: =IF(A43="","",IFERROR(VALUE(MID(A43,4,4)),0)) | W43: =IFERROR(MATCH(C43,Departments!$B$2:$B$13,0),"")
S44: =IF(A44="","",COUNTIF(M44:R44,"Full")*2+COUNTIF(M44:R44,"AM")+COUNTIF(M44:R44,"PM")) | T44: =IF(A44="","",IF(COUNTIF($A$2:$A$200,A44)>1,"Duplicate Staff ID",IF(COUNTA(B44:I44)+COUNTA(K44:L44)<10,"Fill in all details",IF($W44="","Pick a department",IF(COUNTIF(M44:R44,"Off")=6,"No OPD days set",IF((M44<>"Off")*(INDEX(Departments!$D$2:$D$13,$W44)="Closed")+(N44<>"Off")*(INDEX(Departments!$E$2:$E$13,$W44)="Closed")+(O44<>"Off")*(INDEX(Departments!$F$2:$F$13,$W44)="Closed")+(P44<>"Off")*(INDEX(Departments!$G$2:$G$13,$W44)="Closed")+(Q44<>"Off")*(INDEX(Departments!$H$2:$H$13,$W44)="Closed")+(R44<>"Off")*(INDEX(Departments!$I$2:$I$13,$W44)="Closed")>0,"Note: works on a closed OPD day","OK")))))) | U44: =C44&"|"&E44 | V44: =IF(A44="","",IFERROR(VALUE(MID(A44,4,4)),0)) | W44: =IFERROR(MATCH(C44,Departments!$B$2:$B$13,0),"")
S45: =IF(A45="","",COUNTIF(M45:R45,"Full")*2+COUNTIF(M45:R45,"AM")+COUNTIF(M45:R45,"PM")) | T45: =IF(A45="","",IF(COUNTIF($A$2:$A$200,A45)>1,"Duplicate Staff ID",IF(COUNTA(B45:I45)+COUNTA(K45:L45)<10,"Fill in all details",IF($W45="","Pick a department",IF(COUNTIF(M45:R45,"Off")=6,"No OPD days set",IF((M45<>"Off")*(INDEX(Departments!$D$2:$D$13,$W45)="Closed")+(N45<>"Off")*(INDEX(Departments!$E$2:$E$13,$W45)="Closed")+(O45<>"Off")*(INDEX(Departments!$F$2:$F$13,$W45)="Closed")+(P45<>"Off")*(INDEX(Departments!$G$2:$G$13,$W45)="Closed")+(Q45<>"Off")*(INDEX(Departments!$H$2:$H$13,$W45)="Closed")+(R45<>"Off")*(INDEX(Departments!$I$2:$I$13,$W45)="Closed")>0,"Note: works on a closed OPD day","OK")))))) | U45: =C45&"|"&E45 | V45: =IF(A45="","",IFERROR(VALUE(MID(A45,4,4)),0)) | W45: =IFERROR(MATCH(C45,Departments!$B$2:$B$13,0),"")
S46: =IF(A46="","",COUNTIF(M46:R46,"Full")*2+COUNTIF(M46:R46,"AM")+COUNTIF(M46:R46,"PM")) | T46: =IF(A46="","",IF(COUNTIF($A$2:$A$200,A46)>1,"Duplicate Staff ID",IF(COUNTA(B46:I46)+COUNTA(K46:L46)<10,"Fill in all details",IF($W46="","Pick a department",IF(COUNTIF(M46:R46,"Off")=6,"No OPD days set",IF((M46<>"Off")*(INDEX(Departments!$D$2:$D$13,$W46)="Closed")+(N46<>"Off")*(INDEX(Departments!$E$2:$E$13,$W46)="Closed")+(O46<>"Off")*(INDEX(Departments!$F$2:$F$13,$W46)="Closed")+(P46<>"Off")*(INDEX(Departments!$G$2:$G$13,$W46)="Closed")+(Q46<>"Off")*(INDEX(Departments!$H$2:$H$13,$W46)="Closed")+(R46<>"Off")*(INDEX(Departments!$I$2:$I$13,$W46)="Closed")>0,"Note: works on a closed OPD day","OK")))))) | U46: =C46&"|"&E46 | V46: =IF(A46="","",IFERROR(VALUE(MID(A46,4,4)),0)) | W46: =IFERROR(MATCH(C46,Departments!$B$2:$B$13,0),"")
S47: =IF(A47="","",COUNTIF(M47:R47,"Full")*2+COUNTIF(M47:R47,"AM")+COUNTIF(M47:R47,"PM")) | T47: =IF(A47="","",IF(COUNTIF($A$2:$A$200,A47)>1,"Duplicate Staff ID",IF(COUNTA(B47:I47)+COUNTA(K47:L47)<10,"Fill in all details",IF($W47="","Pick a department",IF(COUNTIF(M47:R47,"Off")=6,"No OPD days set",IF((M47<>"Off")*(INDEX(Departments!$D$2:$D$13,$W47)="Closed")+(N47<>"Off")*(INDEX(Departments!$E$2:$E$13,$W47)="Closed")+(O47<>"Off")*(INDEX(Departments!$F$2:$F$13,$W47)="Closed")+(P47<>"Off")*(INDEX(Departments!$G$2:$G$13,$W47)="Closed")+(Q47<>"Off")*(INDEX(Departments!$H$2:$H$13,$W47)="Closed")+(R47<>"Off")*(INDEX(Departments!$I$2:$I$13,$W47)="Closed")>0,"Note: works on a closed OPD day","OK")))))) | U47: =C47&"|"&E47 | V47: =IF(A47="","",IFERROR(VALUE(MID(A47,4,4)),0)) | W47: =IFERROR(MATCH(C47,Departments!$B$2:$B$13,0),"")
S48: =IF(A48="","",COUNTIF(M48:R48,"Full")*2+COUNTIF(M48:R48,"AM")+COUNTIF(M48:R48,"PM")) | T48: =IF(A48="","",IF(COUNTIF($A$2:$A$200,A48)>1,"Duplicate Staff ID",IF(COUNTA(B48:I48)+COUNTA(K48:L48)<10,"Fill in all details",IF($W48="","Pick a department",IF(COUNTIF(M48:R48,"Off")=6,"No OPD days set",IF((M48<>"Off")*(INDEX(Departments!$D$2:$D$13,$W48)="Closed")+(N48<>"Off")*(INDEX(Departments!$E$2:$E$13,$W48)="Closed")+(O48<>"Off")*(INDEX(Departments!$F$2:$F$13,$W48)="Closed")+(P48<>"Off")*(INDEX(Departments!$G$2:$G$13,$W48)="Closed")+(Q48<>"Off")*(INDEX(Departments!$H$2:$H$13,$W48)="Closed")+(R48<>"Off")*(INDEX(Departments!$I$2:$I$13,$W48)="Closed")>0,"Note: works on a closed OPD day","OK")))))) | U48: =C48&"|"&E48 | V48: =IF(A48="","",IFERROR(VALUE(MID(A48,4,4)),0)) | W48: =IFERROR(MATCH(C48,Departments!$B$2:$B$13,0),"")
S49: =IF(A49="","",COUNTIF(M49:R49,"Full")*2+COUNTIF(M49:R49,"AM")+COUNTIF(M49:R49,"PM")) | T49: =IF(A49="","",IF(COUNTIF($A$2:$A$200,A49)>1,"Duplicate Staff ID",IF(COUNTA(B49:I49)+COUNTA(K49:L49)<10,"Fill in all details",IF($W49="","Pick a department",IF(COUNTIF(M49:R49,"Off")=6,"No OPD days set",IF((M49<>"Off")*(INDEX(Departments!$D$2:$D$13,$W49)="Closed")+(N49<>"Off")*(INDEX(Departments!$E$2:$E$13,$W49)="Closed")+(O49<>"Off")*(INDEX(Departments!$F$2:$F$13,$W49)="Closed")+(P49<>"Off")*(INDEX(Departments!$G$2:$G$13,$W49)="Closed")+(Q49<>"Off")*(INDEX(Departments!$H$2:$H$13,$W49)="Closed")+(R49<>"Off")*(INDEX(Departments!$I$2:$I$13,$W49)="Closed")>0,"Note: works on a closed OPD day","OK")))))) | U49: =C49&"|"&E49 | V49: =IF(A49="","",IFERROR(VALUE(MID(A49,4,4)),0)) | W49: =IFERROR(MATCH(C49,Departments!$B$2:$B$13,0),"")
... S200: =IF(A200="","",COUNTIF(M200:R200,"Full")*2+COUNTIF(M200:R200,"AM")+COUNTIF(M200:R200,"PM")) | T200: =IF(A200="","",IF(COUNTIF($A$2:$A$200,A200)>1,"Duplicate Staff ID",IF(COUNTA(B200:I200)+COUNTA(K200:L200)<10,"Fill in all details",IF($W200="","Pick a department",IF(COUNTIF(M200:R200,"Off")=6,"No OPD days set",IF((M200<>"Off")*(INDEX(Departments!$D$2:$D$13,$W200)="Closed")+(N200<>"Off")*(INDEX(Departments!$E$2:$E$13,$W200)="Closed")+(O200<>"Off")*(INDEX(Departments!$F$2:$F$13,$W200)="Closed")+(P200<>"Off")*(INDEX(Departments!$G$2:$G$13,$W200)="Closed")+(Q200<>"Off")*(INDEX(Departments!$H$2:$H$13,$W200)="Closed")+(R200<>"Off")*(INDEX(Departments!$I$2:$I$13,$W200)="Closed")>0,"Note: works on a closed OPD day","OK")))))) | U200: =C200&"|"&E200 | V200: =IF(A200="","",IFERROR(VALUE(MID(A200,4,4)),0)) | W200: =IFERROR(MATCH(C200,Departments!$B$2:$B$13,0),"")

Sheet Departments
A1: Dept ID | B1: Department | C1: Code | D1: Mon | E1: Tue | F1: Wed | G1: Thu | H1: Fri | I1: Sat | J1: Consultation fee | K1: Active doctors | L1: Head of department
A2: DEP0001 | B2: General Medicine | C2: MED | D2: Open | E2: Open | F2: Open | G2: Open | H2: Open | I2: Open | J2: General | K2: =COUNTIFS(Doctors!$C$2:$C$200,B2,Doctors!$K$2:$K$200,"Active") | L2: =IFERROR(INDEX(Doctors!$B$2:$B$200,MATCH(B2&"|Professor & Head",Doctors!$U$2:$U$200,0)),"— none —")
A3: DEP0002 | B3: General Surgery | C3: SUR | D3: Open | E3: Open | F3: Open | G3: Open | H3: Open | I3: Open | J3: Specialist | K3: =COUNTIFS(Doctors!$C$2:$C$200,B3,Doctors!$K$2:$K$200,"Active") | L3: =IFERROR(INDEX(Doctors!$B$2:$B$200,MATCH(B3&"|Professor & Head",Doctors!$U$2:$U$200,0)),"— none —")
A4: DEP0003 | B4: Cardiology | C4: CAR | D4: Open | E4: Closed | F4: Open | G4: Closed | H4: Open | I4: Open | J4: Specialist | K4: =COUNTIFS(Doctors!$C$2:$C$200,B4,Doctors!$K$2:$K$200,"Active") | L4: =IFERROR(INDEX(Doctors!$B$2:$B$200,MATCH(B4&"|Professor & Head",Doctors!$U$2:$U$200,0)),"— none —")
A5: DEP0004 | B5: Orthopaedics | C5: ORT | D5: Open | E5: Open | F5: Closed | G5: Open | H5: Open | I5: Open | J5: Specialist | K5: =COUNTIFS(Doctors!$C$2:$C$200,B5,Doctors!$K$2:$K$200,"Active") | L5: =IFERROR(INDEX(Doctors!$B$2:$B$200,MATCH(B5&"|Professor & Head",Doctors!$U$2:$U$200,0)),"— none —")
A6: DEP0005 | B6: Obstetrics & Gynaecology | C6: OBG | D6: Open | E6: Open | F6: Open | G6: Open | H6: Open | I6: Open | J6: Specialist | K6: =COUNTIFS(Doctors!$C$2:$C$200,B6,Doctors!$K$2:$K$200,"Active") | L6: =IFERROR(INDEX(Doctors!$B$2:$B$200,MATCH(B6&"|Professor & Head",Doctors!$U$2:$U$200,0)),"— none —")
A7: DEP0006 | B7: Paediatrics | C7: PED | D7: Open | E7: Open | F7: Open | G7: Open | H7: Open | I7: Open | J7: Specialist | K7: =COUNTIFS(Doctors!$C$2:$C$200,B7,Doctors!$K$2:$K$200,"Active") | L7: =IFERROR(INDEX(Doctors!$B$2:$B$200,MATCH(B7&"|Professor & Head",Doctors!$U$2:$U$200,0)),"— none —")
A8: DEP0007 | B8: Neurology | C8: NEU | D8: Closed | E8: Open | F8: Closed | G8: Open | H8: Closed | I8: Open | J8: Specialist | K8: =COUNTIFS(Doctors!$C$2:$C$200,B8,Doctors!$K$2:$K$200,"Active") | L8: =IFERROR(INDEX(Doctors!$B$2:$B$200,MATCH(B8&"|Professor & Head",Doctors!$U$2:$U$200,0)),"— none —")
A9: DEP0008 | B9: ENT | C9: ENT | D9: Open | E9: Closed | F9: Open | G9: Closed | H9: Open | I9: Closed | J9: Specialist | K9: =COUNTIFS(Doctors!$C$2:$C$200,B9,Doctors!$K$2:$K$200,"Active") | L9: =IFERROR(INDEX(Doctors!$B$2:$B$200,MATCH(B9&"|Professor & Head",Doctors!$U$2:$U$200,0)),"— none —")
A10: DEP0009 | B10: Ophthalmology | C10: OPH | D10: Open | E10: Open | F10: Open | G10: Open | H10: Open | I10: Open | J10: Specialist | K10: =COUNTIFS(Doctors!$C$2:$C$200,B10,Doctors!$K$2:$K$200,"Active") | L10: =IFERROR(INDEX(Doctors!$B$2:$B$200,MATCH(B10&"|Professor & Head",Doctors!$U$2:$U$200,0)),"— none —")
A11: DEP0010 | B11: Emergency Care | C11: EMR | D11: Open | E11: Open | F11: Open | G11: Open | H11: Open | I11: Open | J11: General | K11: =COUNTIFS(Doctors!$C$2:$C$200,B11,Doctors!$K$2:$K$200,"Active") | L11: =IFERROR(INDEX(Doctors!$B$2:$B$200,MATCH(B11&"|Professor & Head",Doctors!$U$2:$U$200,0)),"— none —")
A12: DEP0011 | B12: Pathology & Laboratory | C12: LAB | D12: Open | E12: Open | F12: Open | G12: Open | H12: Open | I12: Open | J12: Specialist | K12: =COUNTIFS(Doctors!$C$2:$C$200,B12,Doctors!$K$2:$K$200,"Active") | L12: =IFERROR(INDEX(Doctors!$B$2:$B$200,MATCH(B12&"|Professor & Head",Doctors!$U$2:$U$200,0)),"— none —")
A13: DEP0012 | B13: Radiology | C13: RAD | D13: Open | E13: Open | F13: Open | G13: Open | H13: Open | I13: Open | J13: Specialist | K13: =COUNTIFS(Doctors!$C$2:$C$200,B13,Doctors!$K$2:$K$200,"Active") | L13: =IFERROR(INDEX(Doctors!$B$2:$B$200,MATCH(B13&"|Professor & Head",Doctors!$U$2:$U$200,0)),"— none —")
B15: OPD runs Monday–Saturday; Sunday is always closed. Department names and codes are fixed (the website uses them).
B16: Emergency Care is walk-in 24×7 — its OPD days do not limit emergency care.

Sheet Leave
A1: Staff ID | B1: Doctor (auto) | C1: Leave type | D1: From | E1: To | F1: Days (auto) | G1: Reason | H1: Status
B2: =IF(A2="","",IFERROR(INDEX(Doctors!$B$2:$B$200,MATCH(A2,Doctors!$A$2:$A$200,0)),"Unknown Staff ID")) | F2: =IF(OR(D2="",E2=""),"",E2-D2+1)
B3: =IF(A3="","",IFERROR(INDEX(Doctors!$B$2:$B$200,MATCH(A3,Doctors!$A$2:$A$200,0)),"Unknown Staff ID")) | F3: =IF(OR(D3="",E3=""),"",E3-D3+1)
B4: =IF(A4="","",IFERROR(INDEX(Doctors!$B$2:$B$200,MATCH(A4,Doctors!$A$2:$A$200,0)),"Unknown Staff ID")) | F4: =IF(OR(D4="",E4=""),"",E4-D4+1)
B5: =IF(A5="","",IFERROR(INDEX(Doctors!$B$2:$B$200,MATCH(A5,Doctors!$A$2:$A$200,0)),"Unknown Staff ID")) | F5: =IF(OR(D5="",E5=""),"",E5-D5+1)
B6: =IF(A6="","",IFERROR(INDEX(Doctors!$B$2:$B$200,MATCH(A6,Doctors!$A$2:$A$200,0)),"Unknown Staff ID")) | F6: =IF(OR(D6="",E6=""),"",E6-D6+1)
B7: =IF(A7="","",IFERROR(INDEX(Doctors!$B$2:$B$200,MATCH(A7,Doctors!$A$2:$A$200,0)),"Unknown Staff ID")) | F7: =IF(OR(D7="",E7=""),"",E7-D7+1)
B8: =IF(A8="","",IFERROR(INDEX(Doctors!$B$2:$B$200,MATCH(A8,Doctors!$A$2:$A$200,0)),"Unknown Staff ID")) | F8: =IF(OR(D8="",E8=""),"",E8-D8+1)
B9: =IF(A9="","",IFERROR(INDEX(Doctors!$B$2:$B$200,MATCH(A9,Doctors!$A$2:$A$200,0)),"Unknown Staff ID")) | F9: =IF(OR(D9="",E9=""),"",E9-D9+1)
B10: =IF(A10="","",IFERROR(INDEX(Doctors!$B$2:$B$200,MATCH(A10,Doctors!$A$2:$A$200,0)),"Unknown Staff ID")) | F10: =IF(OR(D10="",E10=""),"",E10-D10+1)
B11: =IF(A11="","",IFERROR(INDEX(Doctors!$B$2:$B$200,MATCH(A11,Doctors!$A$2:$A$200,0)),"Unknown Staff ID")) | F11: =IF(OR(D11="",E11=""),"",E11-D11+1)
B12: =IF(A12="","",IFERROR(INDEX(Doctors!$B$2:$B$200,MATCH(A12,Doctors!$A$2:$A$200,0)),"Unknown Staff ID")) | F12: =IF(OR(D12="",E12=""),"",E12-D12+1)
B13: =IF(A13="","",IFERROR(INDEX(Doctors!$B$2:$B$200,MATCH(A13,Doctors!$A$2:$A$200,0)),"Unknown Staff ID")) | F13: =IF(OR(D13="",E13=""),"",E13-D13+1)
... B200: =IF(A200="","",IFERROR(INDEX(Doctors!$B$2:$B$200,MATCH(A200,Doctors!$A$2:$A$200,0)),"Unknown Staff ID")) | F200: =IF(OR(D200="",E200=""),"",E200-D200+1)

Sheet Settings
A1: Setting | B1: Value | C1: Notes
A2: Slot length | B2: 15 | C2: minutes per appointment slot
A3: Morning session starts | B3: 09:00 | C3: hh:mm, 24-hour
A4: Morning session ends | B4: 13:00 | C4: hh:mm, 24-hour
A5: Afternoon session starts | B5: 14:00 | C5: hh:mm, 24-hour
A6: Afternoon session ends | B6: 16:00 | C6: hh:mm, 24-hour
A7: Patients per slot | B7: 1 | C7: bookings allowed in one slot
A8: Booking window | B8: 30 | C8: days ahead patients can book
A9: Consultation fee — General | B9: 300 | C9: ₹, for departments marked General
A10: Consultation fee — Specialist | B10: 600 | C10: ₹, for departments marked Specialist
A11: Follow-up fee | B11: 0 | C11: ₹, within the free follow-up period
A12: Free follow-up period | B12: 14 | C12: days after a completed consultation
A14: Times are text in 24-hour hh:mm form (e.g. 09:00, 14:30). Slot length should divide each session evenly.

Sheet Weekly Coverage
A1: Active doctors available per session (calculated — no need to edit)
B2: Morning (AM) | H2: Afternoon (PM)
A3: Department | B3: Mon | C3: Tue | D3: Wed | E3: Thu | F3: Fri | G3: Sat | H3: Mon | I3: Tue | J3: Wed | K3: Thu | L3: Fri | M3: Sat
A4: =Departments!B2 | B4: =IF(Departments!D2="Closed","Closed",COUNTIFS(Doctors!$C$2:$C$200,$A4,Doctors!$M$2:$M$200,"Full",Doctors!$K$2:$K$200,"Active")+COUNTIFS(Doctors!$C$2:$C$200,$A4,Doctors!$M$2:$M$200,"AM",Doctors!$K$2:$K$200,"Active")) | C4: =IF(Departments!E2="Closed","Closed",COUNTIFS(Doctors!$C$2:$C$200,$A4,Doctors!$N$2:$N$200,"Full",Doctors!$K$2:$K$200,"Active")+COUNTIFS(Doctors!$C$2:$C$200,$A4,Doctors!$N$2:$N$200,"AM",Doctors!$K$2:$K$200,"Active")) | D4: =IF(Departments!F2="Closed","Closed",COUNTIFS(Doctors!$C$2:$C$200,$A4,Doctors!$O$2:$O$200,"Full",Doctors!$K$2:$K$200,"Active")+COUNTIFS(Doctors!$C$2:$C$200,$A4,Doctors!$O$2:$O$200,"AM",Doctors!$K$2:$K$200,"Active")) | E4: =IF(Departments!G2="Closed","Closed",COUNTIFS(Doctors!$C$2:$C$200,$A4,Doctors!$P$2:$P$200,"Full",Doctors!$K$2:$K$200,"Active")+COUNTIFS(Doctors!$C$2:$C$200,$A4,Doctors!$P$2:$P$200,"AM",Doctors!$K$2:$K$200,"Active")) | F4: =IF(Departments!H2="Closed","Closed",COUNTIFS(Doctors!$C$2:$C$200,$A4,Doctors!$Q$2:$Q$200,"Full",Doctors!$K$2:$K$200,"Active")+COUNTIFS(Doctors!$C$2:$C$200,$A4,Doctors!$Q$2:$Q$200,"AM",Doctors!$K$2:$K$200,"Active")) | G4: =IF(Departments!I2="Closed","Closed",COUNTIFS(Doctors!$C$2:$C$200,$A4,Doctors!$R$2:$R$200,"Full",Doctors!$K$2:$K$200,"Active")+COUNTIFS(Doctors!$C$2:$C$200,$A4,Doctors!$R$2:$R$200,"AM",Doctors!$K$2:$K$200,"Active")) | H4: =IF(Departments!D2="Closed","Closed",COUNTIFS(Doctors!$C$2:$C$200,$A4,Doctors!$M$2:$M$200,"Full",Doctors!$K$2:$K$200,"Active")+COUNTIFS(Doctors!$C$2:$C$200,$A4,Doctors!$M$2:$M$200,"PM",Doctors!$K$2:$K$200,"Active")) | I4: =IF(Departments!E2="Closed","Closed",COUNTIFS(Doctors!$C$2:$C$200,$A4,Doctors!$N$2:$N$200,"Full",Doctors!$K$2:$K$200,"Active")+COUNTIFS(Doctors!$C$2:$C$200,$A4,Doctors!$N$2:$N$200,"PM",Doctors!$K$2:$K$200,"Active")) | J4: =IF(Departments!F2="Closed","Closed",COUNTIFS(Doctors!$C$2:$C$200,$A4,Doctors!$O$2:$O$200,"Full",Doctors!$K$2:$K$200,"Active")+COUNTIFS(Doctors!$C$2:$C$200,$A4,Doctors!$O$2:$O$200,"PM",Doctors!$K$2:$K$200,"Active")) | K4: =IF(Departments!G2="Closed","Closed",COUNTIFS(Doctors!$C$2:$C$200,$A4,Doctors!$P$2:$P$200,"Full",Doctors!$K$2:$K$200,"Active")+COUNTIFS(Doctors!$C$2:$C$200,$A4,Doctors!$P$2:$P$200,"PM",Doctors!$K$2:$K$200,"Active")) | L4: =IF(Departments!H2="Closed","Closed",COUNTIFS(Doctors!$C$2:$C$200,$A4,Doctors!$Q$2:$Q$200,"Full",Doctors!$K$2:$K$200,"Active")+COUNTIFS(Doctors!$C$2:$C$200,$A4,Doctors!$Q$2:$Q$200,"PM",Doctors!$K$2:$K$200,"Active")) | M4: =IF(Departments!I2="Closed","Closed",COUNTIFS(Doctors!$C$2:$C$200,$A4,Doctors!$R$2:$R$200,"Full",Doctors!$K$2:$K$200,"Active")+COUNTIFS(Doctors!$C$2:$C$200,$A4,Doctors!$R$2:$R$200,"PM",Doctors!$K$2:$K$200,"Active"))
A5: =Departments!B3 | B5: =IF(Departments!D3="Closed","Closed",COUNTIFS(Doctors!$C$2:$C$200,$A5,Doctors!$M$2:$M$200,"Full",Doctors!$K$2:$K$200,"Active")+COUNTIFS(Doctors!$C$2:$C$200,$A5,Doctors!$M$2:$M$200,"AM",Doctors!$K$2:$K$200,"Active")) | C5: =IF(Departments!E3="Closed","Closed",COUNTIFS(Doctors!$C$2:$C$200,$A5,Doctors!$N$2:$N$200,"Full",Doctors!$K$2:$K$200,"Active")+COUNTIFS(Doctors!$C$2:$C$200,$A5,Doctors!$N$2:$N$200,"AM",Doctors!$K$2:$K$200,"Active")) | D5: =IF(Departments!F3="Closed","Closed",COUNTIFS(Doctors!$C$2:$C$200,$A5,Doctors!$O$2:$O$200,"Full",Doctors!$K$2:$K$200,"Active")+COUNTIFS(Doctors!$C$2:$C$200,$A5,Doctors!$O$2:$O$200,"AM",Doctors!$K$2:$K$200,"Active")) | E5: =IF(Departments!G3="Closed","Closed",COUNTIFS(Doctors!$C$2:$C$200,$A5,Doctors!$P$2:$P$200,"Full",Doctors!$K$2:$K$200,"Active")+COUNTIFS(Doctors!$C$2:$C$200,$A5,Doctors!$P$2:$P$200,"AM",Doctors!$K$2:$K$200,"Active")) | F5: =IF(Departments!H3="Closed","Closed",COUNTIFS(Doctors!$C$2:$C$200,$A5,Doctors!$Q$2:$Q$200,"Full",Doctors!$K$2:$K$200,"Active")+COUNTIFS(Doctors!$C$2:$C$200,$A5,Doctors!$Q$2:$Q$200,"AM",Doctors!$K$2:$K$200,"Active")) | G5: =IF(Departments!I3="Closed","Closed",COUNTIFS(Doctors!$C$2:$C$200,$A5,Doctors!$R$2:$R$200,"Full",Doctors!$K$2:$K$200,"Active")+COUNTIFS(Doctors!$C$2:$C$200,$A5,Doctors!$R$2:$R$200,"AM",Doctors!$K$2:$K$200,"Active")) | H5: =IF(Departments!D3="Closed","Closed",COUNTIFS(Doctors!$C$2:$C$200,$A5,Doctors!$M$2:$M$200,"Full",Doctors!$K$2:$K$200,"Active")+COUNTIFS(Doctors!$C$2:$C$200,$A5,Doctors!$M$2:$M$200,"PM",Doctors!$K$2:$K$200,"Active")) | I5: =IF(Departments!E3="Closed","Closed",COUNTIFS(Doctors!$C$2:$C$200,$A5,Doctors!$N$2:$N$200,"Full",Doctors!$K$2:$K$200,"Active")+COUNTIFS(Doctors!$C$2:$C$200,$A5,Doctors!$N$2:$N$200,"PM",Doctors!$K$2:$K$200,"Active")) | J5: =IF(Departments!F3="Closed","Closed",COUNTIFS(Doctors!$C$2:$C$200,$A5,Doctors!$O$2:$O$200,"Full",Doctors!$K$2:$K$200,"Active")+COUNTIFS(Doctors!$C$2:$C$200,$A5,Doctors!$O$2:$O$200,"PM",Doctors!$K$2:$K$200,"Active")) | K5: =IF(Departments!G3="Closed","Closed",COUNTIFS(Doctors!$C$2:$C$200,$A5,Doctors!$P$2:$P$200,"Full",Doctors!$K$2:$K$200,"Active")+COUNTIFS(Doctors!$C$2:$C$200,$A5,Doctors!$P$2:$P$200,"PM",Doctors!$K$2:$K$200,"Active")) | L5: =IF(Departments!H3="Closed","Closed",COUNTIFS(Doctors!$C$2:$C$200,$A5,Doctors!$Q$2:$Q$200,"Full",Doctors!$K$2:$K$200,"Active")+COUNTIFS(Doctors!$C$2:$C$200,$A5,Doctors!$Q$2:$Q$200,"PM",Doctors!$K$2:$K$200,"Active")) | M5: =IF(Departments!I3="Closed","Closed",COUNTIFS(Doctors!$C$2:$C$200,$A5,Doctors!$R$2:$R$200,"Full",Doctors!$K$2:$K$200,"Active")+COUNTIFS(Doctors!$C$2:$C$200,$A5,Doctors!$R$2:$R$200,"PM",Doctors!$K$2:$K$200,"Active"))
A6: =Departments!B4 | B6: =IF(Departments!D4="Closed","Closed",COUNTIFS(Doctors!$C$2:$C$200,$A6,Doctors!$M$2:$M$200,"Full",Doctors!$K$2:$K$200,"Active")+COUNTIFS(Doctors!$C$2:$C$200,$A6,Doctors!$M$2:$M$200,"AM",Doctors!$K$2:$K$200,"Active")) | C6: =IF(Departments!E4="Closed","Closed",COUNTIFS(Doctors!$C$2:$C$200,$A6,Doctors!$N$2:$N$200,"Full",Doctors!$K$2:$K$200,"Active")+COUNTIFS(Doctors!$C$2:$C$200,$A6,Doctors!$N$2:$N$200,"AM",Doctors!$K$2:$K$200,"Active")) | D6: =IF(Departments!F4="Closed","Closed",COUNTIFS(Doctors!$C$2:$C$200,$A6,Doctors!$O$2:$O$200,"Full",Doctors!$K$2:$K$200,"Active")+COUNTIFS(Doctors!$C$2:$C$200,$A6,Doctors!$O$2:$O$200,"AM",Doctors!$K$2:$K$200,"Active")) | E6: =IF(Departments!G4="Closed","Closed",COUNTIFS(Doctors!$C$2:$C$200,$A6,Doctors!$P$2:$P$200,"Full",Doctors!$K$2:$K$200,"Active")+COUNTIFS(Doctors!$C$2:$C$200,$A6,Doctors!$P$2:$P$200,"AM",Doctors!$K$2:$K$200,"Active")) | F6: =IF(Departments!H4="Closed","Closed",COUNTIFS(Doctors!$C$2:$C$200,$A6,Doctors!$Q$2:$Q$200,"Full",Doctors!$K$2:$K$200,"Active")+COUNTIFS(Doctors!$C$2:$C$200,$A6,Doctors!$Q$2:$Q$200,"AM",Doctors!$K$2:$K$200,"Active")) | G6: =IF(Departments!I4="Closed","Closed",COUNTIFS(Doctors!$C$2:$C$200,$A6,Doctors!$R$2:$R$200,"Full",Doctors!$K$2:$K$200,"Active")+COUNTIFS(Doctors!$C$2:$C$200,$A6,Doctors!$R$2:$R$200,"AM",Doctors!$K$2:$K$200,"Active")) | H6: =IF(Departments!D4="Closed","Closed",COUNTIFS(Doctors!$C$2:$C$200,$A6,Doctors!$M$2:$M$200,"Full",Doctors!$K$2:$K$200,"Active")+COUNTIFS(Doctors!$C$2:$C$200,$A6,Doctors!$M$2:$M$200,"PM",Doctors!$K$2:$K$200,"Active")) | I6: =IF(Departments!E4="Closed","Closed",COUNTIFS(Doctors!$C$2:$C$200,$A6,Doctors!$N$2:$N$200,"Full",Doctors!$K$2:$K$200,"Active")+COUNTIFS(Doctors!$C$2:$C$200,$A6,Doctors!$N$2:$N$200,"PM",Doctors!$K$2:$K$200,"Active")) | J6: =IF(Departments!F4="Closed","Closed",COUNTIFS(Doctors!$C$2:$C$200,$A6,Doctors!$O$2:$O$200,"Full",Doctors!$K$2:$K$200,"Active")+COUNTIFS(Doctors!$C$2:$C$200,$A6,Doctors!$O$2:$O$200,"PM",Doctors!$K$2:$K$200,"Active")) | K6: =IF(Departments!G4="Closed","Closed",COUNTIFS(Doctors!$C$2:$C$200,$A6,Doctors!$P$2:$P$200,"Full",Doctors!$K$2:$K$200,"Active")+COUNTIFS(Doctors!$C$2:$C$200,$A6,Doctors!$P$2:$P$200,"PM",Doctors!$K$2:$K$200,"Active")) | L6: =IF(Departments!H4="Closed","Closed",COUNTIFS(Doctors!$C$2:$C$200,$A6,Doctors!$Q$2:$Q$200,"Full",Doctors!$K$2:$K$200,"Active")+COUNTIFS(Doctors!$C$2:$C$200,$A6,Doctors!$Q$2:$Q$200,"PM",Doctors!$K$2:$K$200,"Active")) | M6: =IF(Departments!I4="Closed","Closed",COUNTIFS(Doctors!$C$2:$C$200,$A6,Doctors!$R$2:$R$200,"Full",Doctors!$K$2:$K$200,"Active")+COUNTIFS(Doctors!$C$2:$C$200,$A6,Doctors!$R$2:$R$200,"PM",Doctors!$K$2:$K$200,"Active"))
A7: =Departments!B5 | B7: =IF(Departments!D5="Closed","Closed",COUNTIFS(Doctors!$C$2:$C$200,$A7,Doctors!$M$2:$M$200,"Full",Doctors!$K$2:$K$200,"Active")+COUNTIFS(Doctors!$C$2:$C$200,$A7,Doctors!$M$2:$M$200,"AM",Doctors!$K$2:$K$200,"Active")) | C7: =IF(Departments!E5="Closed","Closed",COUNTIFS(Doctors!$C$2:$C$200,$A7,Doctors!$N$2:$N$200,"Full",Doctors!$K$2:$K$200,"Active")+COUNTIFS(Doctors!$C$2:$C$200,$A7,Doctors!$N$2:$N$200,"AM",Doctors!$K$2:$K$200,"Active")) | D7: =IF(Departments!F5="Closed","Closed",COUNTIFS(Doctors!$C$2:$C$200,$A7,Doctors!$O$2:$O$200,"Full",Doctors!$K$2:$K$200,"Active")+COUNTIFS(Doctors!$C$2:$C$200,$A7,Doctors!$O$2:$O$200,"AM",Doctors!$K$2:$K$200,"Active")) | E7: =IF(Departments!G5="Closed","Closed",COUNTIFS(Doctors!$C$2:$C$200,$A7,Doctors!$P$2:$P$200,"Full",Doctors!$K$2:$K$200,"Active")+COUNTIFS(Doctors!$C$2:$C$200,$A7,Doctors!$P$2:$P$200,"AM",Doctors!$K$2:$K$200,"Active")) | F7: =IF(Departments!H5="Closed","Closed",COUNTIFS(Doctors!$C$2:$C$200,$A7,Doctors!$Q$2:$Q$200,"Full",Doctors!$K$2:$K$200,"Active")+COUNTIFS(Doctors!$C$2:$C$200,$A7,Doctors!$Q$2:$Q$200,"AM",Doctors!$K$2:$K$200,"Active")) | G7: =IF(Departments!I5="Closed","Closed",COUNTIFS(Doctors!$C$2:$C$200,$A7,Doctors!$R$2:$R$200,"Full",Doctors!$K$2:$K$200,"Active")+COUNTIFS(Doctors!$C$2:$C$200,$A7,Doctors!$R$2:$R$200,"AM",Doctors!$K$2:$K$200,"Active")) | H7: =IF(Departments!D5="Closed","Closed",COUNTIFS(Doctors!$C$2:$C$200,$A7,Doctors!$M$2:$M$200,"Full",Doctors!$K$2:$K$200,"Active")+COUNTIFS(Doctors!$C$2:$C$200,$A7,Doctors!$M$2:$M$200,"PM",Doctors!$K$2:$K$200,"Active")) | I7: =IF(Departments!E5="Closed","Closed",COUNTIFS(Doctors!$C$2:$C$200,$A7,Doctors!$N$2:$N$200,"Full",Doctors!$K$2:$K$200,"Active")+COUNTIFS(Doctors!$C$2:$C$200,$A7,Doctors!$N$2:$N$200,"PM",Doctors!$K$2:$K$200,"Active")) | J7: =IF(Departments!F5="Closed","Closed",COUNTIFS(Doctors!$C$2:$C$200,$A7,Doctors!$O$2:$O$200,"Full",Doctors!$K$2:$K$200,"Active")+COUNTIFS(Doctors!$C$2:$C$200,$A7,Doctors!$O$2:$O$200,"PM",Doctors!$K$2:$K$200,"Active")) | K7: =IF(Departments!G5="Closed","Closed",COUNTIFS(Doctors!$C$2:$C$200,$A7,Doctors!$P$2:$P$200,"Full",Doctors!$K$2:$K$200,"Active")+COUNTIFS(Doctors!$C$2:$C$200,$A7,Doctors!$P$2:$P$200,"PM",Doctors!$K$2:$K$200,"Active")) | L7: =IF(Departments!H5="Closed","Closed",COUNTIFS(Doctors!$C$2:$C$200,$A7,Doctors!$Q$2:$Q$200,"Full",Doctors!$K$2:$K$200,"Active")+COUNTIFS(Doctors!$C$2:$C$200,$A7,Doctors!$Q$2:$Q$200,"PM",Doctors!$K$2:$K$200,"Active")) | M7: =IF(Departments!I5="Closed","Closed",COUNTIFS(Doctors!$C$2:$C$200,$A7,Doctors!$R$2:$R$200,"Full",Doctors!$K$2:$K$200,"Active")+COUNTIFS(Doctors!$C$2:$C$200,$A7,Doctors!$R$2:$R$200,"PM",Doctors!$K$2:$K$200,"Active"))
A8: =Departments!B6 | B8: =IF(Departments!D6="Closed","Closed",COUNTIFS(Doctors!$C$2:$C$200,$A8,Doctors!$M$2:$M$200,"Full",Doctors!$K$2:$K$200,"Active")+COUNTIFS(Doctors!$C$2:$C$200,$A8,Doctors!$M$2:$M$200,"AM",Doctors!$K$2:$K$200,"Active")) | C8: =IF(Departments!E6="Closed","Closed",COUNTIFS(Doctors!$C$2:$C$200,$A8,Doctors!$N$2:$N$200,"Full",Doctors!$K$2:$K$200,"Active")+COUNTIFS(Doctors!$C$2:$C$200,$A8,Doctors!$N$2:$N$200,"AM",Doctors!$K$2:$K$200,"Active")) | D8: =IF(Departments!F6="Closed","Closed",COUNTIFS(Doctors!$C$2:$C$200,$A8,Doctors!$O$2:$O$200,"Full",Doctors!$K$2:$K$200,"Active")+COUNTIFS(Doctors!$C$2:$C$200,$A8,Doctors!$O$2:$O$200,"AM",Doctors!$K$2:$K$200,"Active")) | E8: =IF(Departments!G6="Closed","Closed",COUNTIFS(Doctors!$C$2:$C$200,$A8,Doctors!$P$2:$P$200,"Full",Doctors!$K$2:$K$200,"Active")+COUNTIFS(Doctors!$C$2:$C$200,$A8,Doctors!$P$2:$P$200,"AM",Doctors!$K$2:$K$200,"Active")) | F8: =IF(Departments!H6="Closed","Closed",COUNTIFS(Doctors!$C$2:$C$200,$A8,Doctors!$Q$2:$Q$200,"Full",Doctors!$K$2:$K$200,"Active")+COUNTIFS(Doctors!$C$2:$C$200,$A8,Doctors!$Q$2:$Q$200,"AM",Doctors!$K$2:$K$200,"Active")) | G8: =IF(Departments!I6="Closed","Closed",COUNTIFS(Doctors!$C$2:$C$200,$A8,Doctors!$R$2:$R$200,"Full",Doctors!$K$2:$K$200,"Active")+COUNTIFS(Doctors!$C$2:$C$200,$A8,Doctors!$R$2:$R$200,"AM",Doctors!$K$2:$K$200,"Active")) | H8: =IF(Departments!D6="Closed","Closed",COUNTIFS(Doctors!$C$2:$C$200,$A8,Doctors!$M$2:$M$200,"Full",Doctors!$K$2:$K$200,"Active")+COUNTIFS(Doctors!$C$2:$C$200,$A8,Doctors!$M$2:$M$200,"PM",Doctors!$K$2:$K$200,"Active")) | I8: =IF(Departments!E6="Closed","Closed",COUNTIFS(Doctors!$C$2:$C$200,$A8,Doctors!$N$2:$N$200,"Full",Doctors!$K$2:$K$200,"Active")+COUNTIFS(Doctors!$C$2:$C$200,$A8,Doctors!$N$2:$N$200,"PM",Doctors!$K$2:$K$200,"Active")) | J8: =IF(Departments!F6="Closed","Closed",COUNTIFS(Doctors!$C$2:$C$200,$A8,Doctors!$O$2:$O$200,"Full",Doctors!$K$2:$K$200,"Active")+COUNTIFS(Doctors!$C$2:$C$200,$A8,Doctors!$O$2:$O$200,"PM",Doctors!$K$2:$K$200,"Active")) | K8: =IF(Departments!G6="Closed","Closed",COUNTIFS(Doctors!$C$2:$C$200,$A8,Doctors!$P$2:$P$200,"Full",Doctors!$K$2:$K$200,"Active")+COUNTIFS(Doctors!$C$2:$C$200,$A8,Doctors!$P$2:$P$200,"PM",Doctors!$K$2:$K$200,"Active")) | L8: =IF(Departments!H6="Closed","Closed",COUNTIFS(Doctors!$C$2:$C$200,$A8,Doctors!$Q$2:$Q$200,"Full",Doctors!$K$2:$K$200,"Active")+COUNTIFS(Doctors!$C$2:$C$200,$A8,Doctors!$Q$2:$Q$200,"PM",Doctors!$K$2:$K$200,"Active")) | M8: =IF(Departments!I6="Closed","Closed",COUNTIFS(Doctors!$C$2:$C$200,$A8,Doctors!$R$2:$R$200,"Full",Doctors!$K$2:$K$200,"Active")+COUNTIFS(Doctors!$C$2:$C$200,$A8,Doctors!$R$2:$R$200,"PM",Doctors!$K$2:$K$200,"Active"))
A9: =Departments!B7 | B9: =IF(Departments!D7="Closed","Closed",COUNTIFS(Doctors!$C$2:$C$200,$A9,Doctors!$M$2:$M$200,"Full",Doctors!$K$2:$K$200,"Active")+COUNTIFS(Doctors!$C$2:$C$200,$A9,Doctors!$M$2:$M$200,"AM",Doctors!$K$2:$K$200,"Active")) | C9: =IF(Departments!E7="Closed","Closed",COUNTIFS(Doctors!$C$2:$C$200,$A9,Doctors!$N$2:$N$200,"Full",Doctors!$K$2:$K$200,"Active")+COUNTIFS(Doctors!$C$2:$C$200,$A9,Doctors!$N$2:$N$200,"AM",Doctors!$K$2:$K$200,"Active")) | D9: =IF(Departments!F7="Closed","Closed",COUNTIFS(Doctors!$C$2:$C$200,$A9,Doctors!$O$2:$O$200,"Full",Doctors!$K$2:$K$200,"Active")+COUNTIFS(Doctors!$C$2:$C$200,$A9,Doctors!$O$2:$O$200,"AM",Doctors!$K$2:$K$200,"Active")) | E9: =IF(Departments!G7="Closed","Closed",COUNTIFS(Doctors!$C$2:$C$200,$A9,Doctors!$P$2:$P$200,"Full",Doctors!$K$2:$K$200,"Active")+COUNTIFS(Doctors!$C$2:$C$200,$A9,Doctors!$P$2:$P$200,"AM",Doctors!$K$2:$K$200,"Active")) | F9: =IF(Departments!H7="Closed","Closed",COUNTIFS(Doctors!$C$2:$C$200,$A9,Doctors!$Q$2:$Q$200,"Full",Doctors!$K$2:$K$200,"Active")+COUNTIFS(Doctors!$C$2:$C$200,$A9,Doctors!$Q$2:$Q$200,"AM",Doctors!$K$2:$K$200,"Active")) | G9: =IF(Departments!I7="Closed","Closed",COUNTIFS(Doctors!$C$2:$C$200,$A9,Doctors!$R$2:$R$200,"Full",Doctors!$K$2:$K$200,"Active")+COUNTIFS(Doctors!$C$2:$C$200,$A9,Doctors!$R$2:$R$200,"AM",Doctors!$K$2:$K$200,"Active")) | H9: =IF(Departments!D7="Closed","Closed",COUNTIFS(Doctors!$C$2:$C$200,$A9,Doctors!$M$2:$M$200,"Full",Doctors!$K$2:$K$200,"Active")+COUNTIFS(Doctors!$C$2:$C$200,$A9,Doctors!$M$2:$M$200,"PM",Doctors!$K$2:$K$200,"Active")) | I9: =IF(Departments!E7="Closed","Closed",COUNTIFS(Doctors!$C$2:$C$200,$A9,Doctors!$N$2:$N$200,"Full",Doctors!$K$2:$K$200,"Active")+COUNTIFS(Doctors!$C$2:$C$200,$A9,Doctors!$N$2:$N$200,"PM",Doctors!$K$2:$K$200,"Active")) | J9: =IF(Departments!F7="Closed","Closed",COUNTIFS(Doctors!$C$2:$C$200,$A9,Doctors!$O$2:$O$200,"Full",Doctors!$K$2:$K$200,"Active")+COUNTIFS(Doctors!$C$2:$C$200,$A9,Doctors!$O$2:$O$200,"PM",Doctors!$K$2:$K$200,"Active")) | K9: =IF(Departments!G7="Closed","Closed",COUNTIFS(Doctors!$C$2:$C$200,$A9,Doctors!$P$2:$P$200,"Full",Doctors!$K$2:$K$200,"Active")+COUNTIFS(Doctors!$C$2:$C$200,$A9,Doctors!$P$2:$P$200,"PM",Doctors!$K$2:$K$200,"Active")) | L9: =IF(Departments!H7="Closed","Closed",COUNTIFS(Doctors!$C$2:$C$200,$A9,Doctors!$Q$2:$Q$200,"Full",Doctors!$K$2:$K$200,"Active")+COUNTIFS(Doctors!$C$2:$C$200,$A9,Doctors!$Q$2:$Q$200,"PM",Doctors!$K$2:$K$200,"Active")) | M9: =IF(Departments!I7="Closed","Closed",COUNTIFS(Doctors!$C$2:$C$200,$A9,Doctors!$R$2:$R$200,"Full",Doctors!$K$2:$K$200,"Active")+COUNTIFS(Doctors!$C$2:$C$200,$A9,Doctors!$R$2:$R$200,"PM",Doctors!$K$2:$K$200,"Active"))
A10: =Departments!B8 | B10: =IF(Departments!D8="Closed","Closed",COUNTIFS(Doctors!$C$2:$C$200,$A10,Doctors!$M$2:$M$200,"Full",Doctors!$K$2:$K$200,"Active")+COUNTIFS(Doctors!$C$2:$C$200,$A10,Doctors!$M$2:$M$200,"AM",Doctors!$K$2:$K$200,"Active")) | C10: =IF(Departments!E8="Closed","Closed",COUNTIFS(Doctors!$C$2:$C$200,$A10,Doctors!$N$2:$N$200,"Full",Doctors!$K$2:$K$200,"Active")+COUNTIFS(Doctors!$C$2:$C$200,$A10,Doctors!$N$2:$N$200,"AM",Doctors!$K$2:$K$200,"Active")) | D10: =IF(Departments!F8="Closed","Closed",COUNTIFS(Doctors!$C$2:$C$200,$A10,Doctors!$O$2:$O$200,"Full",Doctors!$K$2:$K$200,"Active")+COUNTIFS(Doctors!$C$2:$C$200,$A10,Doctors!$O$2:$O$200,"AM",Doctors!$K$2:$K$200,"Active")) | E10: =IF(Departments!G8="Closed","Closed",COUNTIFS(Doctors!$C$2:$C$200,$A10,Doctors!$P$2:$P$200,"Full",Doctors!$K$2:$K$200,"Active")+COUNTIFS(Doctors!$C$2:$C$200,$A10,Doctors!$P$2:$P$200,"AM",Doctors!$K$2:$K$200,"Active")) | F10: =IF(Departments!H8="Closed","Closed",COUNTIFS(Doctors!$C$2:$C$200,$A10,Doctors!$Q$2:$Q$200,"Full",Doctors!$K$2:$K$200,"Active")+COUNTIFS(Doctors!$C$2:$C$200,$A10,Doctors!$Q$2:$Q$200,"AM",Doctors!$K$2:$K$200,"Active")) | G10: =IF(Departments!I8="Closed","Closed",COUNTIFS(Doctors!$C$2:$C$200,$A10,Doctors!$R$2:$R$200,"Full",Doctors!$K$2:$K$200,"Active")+COUNTIFS(Doctors!$C$2:$C$200,$A10,Doctors!$R$2:$R$200,"AM",Doctors!$K$2:$K$200,"Active")) | H10: =IF(Departments!D8="Closed","Closed",COUNTIFS(Doctors!$C$2:$C$200,$A10,Doctors!$M$2:$M$200,"Full",Doctors!$K$2:$K$200,"Active")+COUNTIFS(Doctors!$C$2:$C$200,$A10,Doctors!$M$2:$M$200,"PM",Doctors!$K$2:$K$200,"Active")) | I10: =IF(Departments!E8="Closed","Closed",COUNTIFS(Doctors!$C$2:$C$200,$A10,Doctors!$N$2:$N$200,"Full",Doctors!$K$2:$K$200,"Active")+COUNTIFS(Doctors!$C$2:$C$200,$A10,Doctors!$N$2:$N$200,"PM",Doctors!$K$2:$K$200,"Active")) | J10: =IF(Departments!F8="Closed","Closed",COUNTIFS(Doctors!$C$2:$C$200,$A10,Doctors!$O$2:$O$200,"Full",Doctors!$K$2:$K$200,"Active")+COUNTIFS(Doctors!$C$2:$C$200,$A10,Doctors!$O$2:$O$200,"PM",Doctors!$K$2:$K$200,"Active")) | K10: =IF(Departments!G8="Closed","Closed",COUNTIFS(Doctors!$C$2:$C$200,$A10,Doctors!$P$2:$P$200,"Full",Doctors!$K$2:$K$200,"Active")+COUNTIFS(Doctors!$C$2:$C$200,$A10,Doctors!$P$2:$P$200,"PM",Doctors!$K$2:$K$200,"Active")) | L10: =IF(Departments!H8="Closed","Closed",COUNTIFS(Doctors!$C$2:$C$200,$A10,Doctors!$Q$2:$Q$200,"Full",Doctors!$K$2:$K$200,"Active")+COUNTIFS(Doctors!$C$2:$C$200,$A10,Doctors!$Q$2:$Q$200,"PM",Doctors!$K$2:$K$200,"Active")) | M10: =IF(Departments!I8="Closed","Closed",COUNTIFS(Doctors!$C$2:$C$200,$A10,Doctors!$R$2:$R$200,"Full",Doctors!$K$2:$K$200,"Active")+COUNTIFS(Doctors!$C$2:$C$200,$A10,Doctors!$R$2:$R$200,"PM",Doctors!$K$2:$K$200,"Active"))
A11: =Departments!B9 | B11: =IF(Departments!D9="Closed","Closed",COUNTIFS(Doctors!$C$2:$C$200,$A11,Doctors!$M$2:$M$200,"Full",Doctors!$K$2:$K$200,"Active")+COUNTIFS(Doctors!$C$2:$C$200,$A11,Doctors!$M$2:$M$200,"AM",Doctors!$K$2:$K$200,"Active")) | C11: =IF(Departments!E9="Closed","Closed",COUNTIFS(Doctors!$C$2:$C$200,$A11,Doctors!$N$2:$N$200,"Full",Doctors!$K$2:$K$200,"Active")+COUNTIFS(Doctors!$C$2:$C$200,$A11,Doctors!$N$2:$N$200,"AM",Doctors!$K$2:$K$200,"Active")) | D11: =IF(Departments!F9="Closed","Closed",COUNTIFS(Doctors!$C$2:$C$200,$A11,Doctors!$O$2:$O$200,"Full",Doctors!$K$2:$K$200,"Active")+COUNTIFS(Doctors!$C$2:$C$200,$A11,Doctors!$O$2:$O$200,"AM",Doctors!$K$2:$K$200,"Active")) | E11: =IF(Departments!G9="Closed","Closed",COUNTIFS(Doctors!$C$2:$C$200,$A11,Doctors!$P$2:$P$200,"Full",Doctors!$K$2:$K$200,"Active")+COUNTIFS(Doctors!$C$2:$C$200,$A11,Doctors!$P$2:$P$200,"AM",Doctors!$K$2:$K$200,"Active")) | F11: =IF(Departments!H9="Closed","Closed",COUNTIFS(Doctors!$C$2:$C$200,$A11,Doctors!$Q$2:$Q$200,"Full",Doctors!$K$2:$K$200,"Active")+COUNTIFS(Doctors!$C$2:$C$200,$A11,Doctors!$Q$2:$Q$200,"AM",Doctors!$K$2:$K$200,"Active")) | G11: =IF(Departments!I9="Closed","Closed",COUNTIFS(Doctors!$C$2:$C$200,$A11,Doctors!$R$2:$R$200,"Full",Doctors!$K$2:$K$200,"Active")+COUNTIFS(Doctors!$C$2:$C$200,$A11,Doctors!$R$2:$R$200,"AM",Doctors!$K$2:$K$200,"Active")) | H11: =IF(Departments!D9="Closed","Closed",COUNTIFS(Doctors!$C$2:$C$200,$A11,Doctors!$M$2:$M$200,"Full",Doctors!$K$2:$K$200,"Active")+COUNTIFS(Doctors!$C$2:$C$200,$A11,Doctors!$M$2:$M$200,"PM",Doctors!$K$2:$K$200,"Active")) | I11: =IF(Departments!E9="Closed","Closed",COUNTIFS(Doctors!$C$2:$C$200,$A11,Doctors!$N$2:$N$200,"Full",Doctors!$K$2:$K$200,"Active")+COUNTIFS(Doctors!$C$2:$C$200,$A11,Doctors!$N$2:$N$200,"PM",Doctors!$K$2:$K$200,"Active")) | J11: =IF(Departments!F9="Closed","Closed",COUNTIFS(Doctors!$C$2:$C$200,$A11,Doctors!$O$2:$O$200,"Full",Doctors!$K$2:$K$200,"Active")+COUNTIFS(Doctors!$C$2:$C$200,$A11,Doctors!$O$2:$O$200,"PM",Doctors!$K$2:$K$200,"Active")) | K11: =IF(Departments!G9="Closed","Closed",COUNTIFS(Doctors!$C$2:$C$200,$A11,Doctors!$P$2:$P$200,"Full",Doctors!$K$2:$K$200,"Active")+COUNTIFS(Doctors!$C$2:$C$200,$A11,Doctors!$P$2:$P$200,"PM",Doctors!$K$2:$K$200,"Active")) | L11: =IF(Departments!H9="Closed","Closed",COUNTIFS(Doctors!$C$2:$C$200,$A11,Doctors!$Q$2:$Q$200,"Full",Doctors!$K$2:$K$200,"Active")+COUNTIFS(Doctors!$C$2:$C$200,$A11,Doctors!$Q$2:$Q$200,"PM",Doctors!$K$2:$K$200,"Active")) | M11: =IF(Departments!I9="Closed","Closed",COUNTIFS(Doctors!$C$2:$C$200,$A11,Doctors!$R$2:$R$200,"Full",Doctors!$K$2:$K$200,"Active")+COUNTIFS(Doctors!$C$2:$C$200,$A11,Doctors!$R$2:$R$200,"PM",Doctors!$K$2:$K$200,"Active"))
